Failure # 1 (occurred at 2024-03-24_18-27-29)
The actor died because of an error raised in its creation task, [36mray::PPO.__init__()[39m (pid=4248, ip=127.0.0.1, actor_id=28bc94a7e7a5177d1089ab0801000000, repr=PPO)
  File "python\ray\_raylet.pyx", line 1616, in ray._raylet.execute_task
  File "python\ray\_raylet.pyx", line 1556, in ray._raylet.execute_task.function_executor
  File "C:\Users\josep\Documents\Coup-RL\env\lib\site-packages\ray\_private\function_manager.py", line 726, in actor_method_executor
    return method(__ray_actor, *args, **kwargs)
  File "C:\Users\josep\Documents\Coup-RL\env\lib\site-packages\ray\util\tracing\tracing_helper.py", line 467, in _resume_span
    return method(self, *_args, **_kwargs)
  File "C:\Users\josep\Documents\Coup-RL\env\lib\site-packages\ray\rllib\algorithms\algorithm.py", line 517, in __init__
    super().__init__(
  File "C:\Users\josep\Documents\Coup-RL\env\lib\site-packages\ray\tune\trainable\trainable.py", line 185, in __init__
    self.setup(copy.deepcopy(self.config))
  File "C:\Users\josep\Documents\Coup-RL\env\lib\site-packages\ray\util\tracing\tracing_helper.py", line 467, in _resume_span
    return method(self, *_args, **_kwargs)
  File "C:\Users\josep\Documents\Coup-RL\env\lib\site-packages\ray\rllib\algorithms\algorithm.py", line 639, in setup
    self.workers = WorkerSet(
  File "C:\Users\josep\Documents\Coup-RL\env\lib\site-packages\ray\rllib\evaluation\worker_set.py", line 157, in __init__
    self._setup(
  File "C:\Users\josep\Documents\Coup-RL\env\lib\site-packages\ray\rllib\evaluation\worker_set.py", line 227, in _setup
    self.add_workers(
  File "C:\Users\josep\Documents\Coup-RL\env\lib\site-packages\ray\rllib\evaluation\worker_set.py", line 593, in add_workers
    raise result.get()
ray.exceptions.RayTaskError(AssertionError): [36mray::RolloutWorker.apply()[39m (pid=31124, ip=127.0.0.1, actor_id=aa6f35b7ff10609791d82ba501000000, repr=<ray.rllib.evaluation.rollout_worker.RolloutWorker object at 0x000001CCBC2C8AC0>)
  File "python\ray\_raylet.pyx", line 1616, in ray._raylet.execute_task
  File "python\ray\_raylet.pyx", line 1556, in ray._raylet.execute_task.function_executor
  File "C:\Users\josep\Documents\Coup-RL\env\lib\site-packages\ray\_private\function_manager.py", line 726, in actor_method_executor
    return method(__ray_actor, *args, **kwargs)
  File "C:\Users\josep\Documents\Coup-RL\env\lib\site-packages\ray\util\tracing\tracing_helper.py", line 467, in _resume_span
    return method(self, *_args, **_kwargs)
  File "C:\Users\josep\Documents\Coup-RL\env\lib\site-packages\ray\rllib\utils\actor_manager.py", line 185, in apply
    raise e
  File "C:\Users\josep\Documents\Coup-RL\env\lib\site-packages\ray\rllib\utils\actor_manager.py", line 176, in apply
    return func(self, *args, **kwargs)
  File "C:\Users\josep\Documents\Coup-RL\env\lib\site-packages\ray\rllib\evaluation\worker_set.py", line 588, in <lambda>
    lambda w: w.assert_healthy()
  File "C:\Users\josep\Documents\Coup-RL\env\lib\site-packages\ray\util\tracing\tracing_helper.py", line 467, in _resume_span
    return method(self, *_args, **_kwargs)
  File "C:\Users\josep\Documents\Coup-RL\env\lib\site-packages\ray\rllib\evaluation\rollout_worker.py", line 654, in assert_healthy
    assert is_healthy, (
AssertionError: RolloutWorker <ray.rllib.evaluation.rollout_worker.RolloutWorker object at 0x000001CCBC2C8AC0> (idx=1; num_workers=2) not healthy!
