Failure # 1 (occurred at 2024-04-21_17-36-26)
[36mray::PPO.train()[39m (pid=2612, ip=127.0.0.1, actor_id=0e36905728b448ac95c6737301000000, repr=PPO)
  File "python\ray\_raylet.pyx", line 1889, in ray._raylet.execute_task
  File "python\ray\_raylet.pyx", line 1830, in ray._raylet.execute_task.function_executor
  File "D:\Documents\Coup-RL\env\lib\site-packages\ray\_private\function_manager.py", line 724, in actor_method_executor
    return method(__ray_actor, *args, **kwargs)
  File "D:\Documents\Coup-RL\env\lib\site-packages\ray\util\tracing\tracing_helper.py", line 467, in _resume_span
    return method(self, *_args, **_kwargs)
  File "D:\Documents\Coup-RL\env\lib\site-packages\ray\tune\trainable\trainable.py", line 334, in train
    raise skipped from exception_cause(skipped)
  File "D:\Documents\Coup-RL\env\lib\site-packages\ray\tune\trainable\trainable.py", line 331, in train
    result = self.step()
  File "D:\Documents\Coup-RL\env\lib\site-packages\ray\util\tracing\tracing_helper.py", line 467, in _resume_span
    return method(self, *_args, **_kwargs)
  File "D:\Documents\Coup-RL\env\lib\site-packages\ray\rllib\algorithms\algorithm.py", line 853, in step
    results.update(self._run_one_evaluation(train_future=None))
  File "D:\Documents\Coup-RL\env\lib\site-packages\ray\util\tracing\tracing_helper.py", line 467, in _resume_span
    return method(self, *_args, **_kwargs)
  File "D:\Documents\Coup-RL\env\lib\site-packages\ray\rllib\algorithms\algorithm.py", line 3239, in _run_one_evaluation
    eval_results = eval_func_to_use()
  File "D:\Documents\Coup-RL\env\lib\site-packages\ray\util\tracing\tracing_helper.py", line 467, in _resume_span
    return method(self, *_args, **_kwargs)
  File "D:\Documents\Coup-RL\env\lib\site-packages\ray\rllib\algorithms\algorithm.py", line 948, in evaluate
    metrics = self.config.custom_evaluation_function(
  File "D:\Documents\Coup-RL\Coup\coup\train_ppo.py", line 286, in custom_eval_function
    eval_policy_tests(eval_workers, metrics)
  File "D:\Documents\Coup-RL\Coup\coup\train_ppo.py", line 258, in eval_policy_tests
    int(scenario_tests.foreign_aid_test(policy, env)),
  File "D:\Documents\Coup-RL\Coup\coup\scenario_tests.py", line 72, in foreign_aid_test
    actions = [env.get_action_id("foreign_aid"), env.get_action_id("counteract"), env.get_action_id("pass"), env.get_action_id("tax"), env.get_action_id("pass"), env.get_action_id("pass")]
AttributeError: 'PettingZooEnv' object has no attribute 'get_action_id'
