Failure # 1 (occurred at 2024-03-26_20-10-30)
[36mray::PPO.train()[39m (pid=4132, ip=127.0.0.1, actor_id=a5880cfe607c2398d596df8001000000, repr=PPO)
  File "python\ray\_raylet.pyx", line 1889, in ray._raylet.execute_task
  File "python\ray\_raylet.pyx", line 1830, in ray._raylet.execute_task.function_executor
  File "C:\Users\josep\Documents\Coup-RL\env\lib\site-packages\ray\_private\function_manager.py", line 724, in actor_method_executor
    return method(__ray_actor, *args, **kwargs)
  File "C:\Users\josep\Documents\Coup-RL\env\lib\site-packages\ray\util\tracing\tracing_helper.py", line 467, in _resume_span
    return method(self, *_args, **_kwargs)
  File "C:\Users\josep\Documents\Coup-RL\env\lib\site-packages\ray\tune\trainable\trainable.py", line 334, in train
    raise skipped from exception_cause(skipped)
  File "C:\Users\josep\Documents\Coup-RL\env\lib\site-packages\ray\tune\trainable\trainable.py", line 331, in train
    result = self.step()
  File "C:\Users\josep\Documents\Coup-RL\env\lib\site-packages\ray\util\tracing\tracing_helper.py", line 467, in _resume_span
    return method(self, *_args, **_kwargs)
  File "C:\Users\josep\Documents\Coup-RL\env\lib\site-packages\ray\rllib\algorithms\algorithm.py", line 853, in step
    results.update(self._run_one_evaluation(train_future=None))
  File "C:\Users\josep\Documents\Coup-RL\env\lib\site-packages\ray\util\tracing\tracing_helper.py", line 467, in _resume_span
    return method(self, *_args, **_kwargs)
  File "C:\Users\josep\Documents\Coup-RL\env\lib\site-packages\ray\rllib\algorithms\algorithm.py", line 3239, in _run_one_evaluation
    eval_results = eval_func_to_use()
  File "C:\Users\josep\Documents\Coup-RL\env\lib\site-packages\ray\util\tracing\tracing_helper.py", line 467, in _resume_span
    return method(self, *_args, **_kwargs)
  File "C:\Users\josep\Documents\Coup-RL\env\lib\site-packages\ray\rllib\algorithms\algorithm.py", line 948, in evaluate
    metrics = self.config.custom_evaluation_function(
  File "C:\Users\josep\Documents\Coup-RL\Coup\coup\train_ppo.py", line 93, in custom_eval_function
    eval_workers.foreach_worker(
  File "C:\Users\josep\Documents\Coup-RL\env\lib\site-packages\ray\rllib\evaluation\worker_set.py", line 757, in foreach_worker
    local_result = [func(self.local_worker())]
  File "C:\Users\josep\Documents\Coup-RL\Coup\coup\train_ppo.py", line 96, in <lambda>
    func=lambda w: w.foreach_policy(
  File "C:\Users\josep\Documents\Coup-RL\env\lib\site-packages\ray\rllib\evaluation\rollout_worker.py", line 1325, in foreach_policy
    return [func(policy, pid, **kwargs) for pid, policy in self.policy_map.items()]
  File "C:\Users\josep\Documents\Coup-RL\env\lib\site-packages\ray\rllib\evaluation\rollout_worker.py", line 1325, in <listcomp>
    return [func(policy, pid, **kwargs) for pid, policy in self.policy_map.items()]
TypeError: custom_eval_function.<locals>.<lambda>.<locals>.<lambda>() takes 1 positional argument but 2 were given
