Failure # 1 (occurred at 2024-03-26_21-36-59)
[36mray::PPO.train()[39m (pid=18272, ip=127.0.0.1, actor_id=4dbda676669c88fac09aa75101000000, repr=PPO)
  File "python\ray\_raylet.pyx", line 1889, in ray._raylet.execute_task
  File "python\ray\_raylet.pyx", line 1830, in ray._raylet.execute_task.function_executor
  File "C:\Users\josep\Documents\Coup-RL\env\lib\site-packages\ray\_private\function_manager.py", line 724, in actor_method_executor
    return method(__ray_actor, *args, **kwargs)
  File "C:\Users\josep\Documents\Coup-RL\env\lib\site-packages\ray\util\tracing\tracing_helper.py", line 467, in _resume_span
    return method(self, *_args, **_kwargs)
  File "C:\Users\josep\Documents\Coup-RL\env\lib\site-packages\ray\tune\trainable\trainable.py", line 334, in train
    raise skipped from exception_cause(skipped)
  File "C:\Users\josep\Documents\Coup-RL\env\lib\site-packages\ray\tune\trainable\trainable.py", line 331, in train
    result = self.step()
  File "C:\Users\josep\Documents\Coup-RL\env\lib\site-packages\ray\util\tracing\tracing_helper.py", line 467, in _resume_span
    return method(self, *_args, **_kwargs)
  File "C:\Users\josep\Documents\Coup-RL\env\lib\site-packages\ray\rllib\algorithms\algorithm.py", line 853, in step
    results.update(self._run_one_evaluation(train_future=None))
  File "C:\Users\josep\Documents\Coup-RL\env\lib\site-packages\ray\util\tracing\tracing_helper.py", line 467, in _resume_span
    return method(self, *_args, **_kwargs)
  File "C:\Users\josep\Documents\Coup-RL\env\lib\site-packages\ray\rllib\algorithms\algorithm.py", line 3244, in _run_one_evaluation
    self.restore_workers(self.evaluation_workers)
  File "C:\Users\josep\Documents\Coup-RL\env\lib\site-packages\ray\util\tracing\tracing_helper.py", line 467, in _resume_span
    return method(self, *_args, **_kwargs)
  File "C:\Users\josep\Documents\Coup-RL\env\lib\site-packages\ray\rllib\algorithms\algorithm.py", line 1602, in restore_workers
    restored = workers.probe_unhealthy_workers()
  File "C:\Users\josep\Documents\Coup-RL\env\lib\site-packages\ray\rllib\evaluation\worker_set.py", line 987, in probe_unhealthy_workers
    timeout_seconds=self._remote_config.worker_health_probe_timeout_s
AttributeError: 'dict' object has no attribute 'worker_health_probe_timeout_s'
