Failure # 1 (occurred at 2024-03-26_14-33-07)
[36mray::PPO.train()[39m (pid=21764, ip=127.0.0.1, actor_id=90f971edda22ac0916e46d5201000000, repr=PPO)
  File "python\ray\_raylet.pyx", line 1889, in ray._raylet.execute_task
  File "python\ray\_raylet.pyx", line 1830, in ray._raylet.execute_task.function_executor
  File "C:\Users\josep\Documents\Coup-RL\env\lib\site-packages\ray\_private\function_manager.py", line 724, in actor_method_executor
    return method(__ray_actor, *args, **kwargs)
  File "C:\Users\josep\Documents\Coup-RL\env\lib\site-packages\ray\util\tracing\tracing_helper.py", line 467, in _resume_span
    return method(self, *_args, **_kwargs)
  File "C:\Users\josep\Documents\Coup-RL\env\lib\site-packages\ray\tune\trainable\trainable.py", line 334, in train
    raise skipped from exception_cause(skipped)
  File "C:\Users\josep\Documents\Coup-RL\env\lib\site-packages\ray\tune\trainable\trainable.py", line 331, in train
    result = self.step()
  File "C:\Users\josep\Documents\Coup-RL\env\lib\site-packages\ray\util\tracing\tracing_helper.py", line 467, in _resume_span
    return method(self, *_args, **_kwargs)
  File "C:\Users\josep\Documents\Coup-RL\env\lib\site-packages\ray\rllib\algorithms\algorithm.py", line 853, in step
    results.update(self._run_one_evaluation(train_future=None))
  File "C:\Users\josep\Documents\Coup-RL\env\lib\site-packages\ray\util\tracing\tracing_helper.py", line 467, in _resume_span
    return method(self, *_args, **_kwargs)
  File "C:\Users\josep\Documents\Coup-RL\env\lib\site-packages\ray\rllib\algorithms\algorithm.py", line 3239, in _run_one_evaluation
    eval_results = eval_func_to_use()
  File "C:\Users\josep\Documents\Coup-RL\env\lib\site-packages\ray\util\tracing\tracing_helper.py", line 467, in _resume_span
    return method(self, *_args, **_kwargs)
  File "C:\Users\josep\Documents\Coup-RL\env\lib\site-packages\ray\rllib\algorithms\algorithm.py", line 948, in evaluate
    metrics = self.config.custom_evaluation_function(
  File "C:\Users\josep\Documents\Coup-RL\Coup\coup\train_ppo.py", line 49, in custom_eval_function
    eval_workers.foreach_worker(
  File "C:\Users\josep\Documents\Coup-RL\env\lib\site-packages\ray\rllib\evaluation\worker_set.py", line 771, in foreach_worker
    handle_remote_call_result_errors(remote_results, self._ignore_worker_failures)
  File "C:\Users\josep\Documents\Coup-RL\env\lib\site-packages\ray\rllib\evaluation\worker_set.py", line 78, in handle_remote_call_result_errors
    raise r.get()
ray.exceptions.RayTaskError(AttributeError): [36mray::RolloutWorker.apply()[39m (pid=13300, ip=127.0.0.1, actor_id=8d93bfbe5caa50f7ffb0a66701000000, repr=<ray.rllib.evaluation.rollout_worker.RolloutWorker object at 0x000002271F018BE0>)
  File "python\ray\_raylet.pyx", line 1889, in ray._raylet.execute_task
  File "python\ray\_raylet.pyx", line 1830, in ray._raylet.execute_task.function_executor
  File "C:\Users\josep\Documents\Coup-RL\env\lib\site-packages\ray\_private\function_manager.py", line 724, in actor_method_executor
    return method(__ray_actor, *args, **kwargs)
  File "C:\Users\josep\Documents\Coup-RL\env\lib\site-packages\ray\util\tracing\tracing_helper.py", line 467, in _resume_span
    return method(self, *_args, **_kwargs)
  File "C:\Users\josep\Documents\Coup-RL\env\lib\site-packages\ray\rllib\utils\actor_manager.py", line 189, in apply
    raise e
  File "C:\Users\josep\Documents\Coup-RL\env\lib\site-packages\ray\rllib\utils\actor_manager.py", line 178, in apply
    return func(self, *args, **kwargs)
  File "C:\Users\josep\Documents\Coup-RL\Coup\coup\train_ppo.py", line 50, in <lambda>
    func=lambda w: w.foreach_env(
  File "C:\Users\josep\Documents\Coup-RL\env\lib\site-packages\ray\util\tracing\tracing_helper.py", line 467, in _resume_span
    return method(self, *_args, **_kwargs)
  File "C:\Users\josep\Documents\Coup-RL\env\lib\site-packages\ray\rllib\evaluation\rollout_worker.py", line 1037, in foreach_env
    return [func(e) for e in envs]
  File "C:\Users\josep\Documents\Coup-RL\env\lib\site-packages\ray\rllib\evaluation\rollout_worker.py", line 1037, in <listcomp>
    return [func(e) for e in envs]
  File "C:\Users\josep\Documents\Coup-RL\Coup\coup\train_ppo.py", line 51, in <lambda>
    lambda env: env.set_corridor_length(4 if w.worker_index == 1 else 7)
AttributeError: 'PettingZooEnv' object has no attribute 'set_corridor_length'
