Failure # 1 (occurred at 2024-03-27_13-38-34)
[36mray::PPO.train()[39m (pid=21480, ip=127.0.0.1, actor_id=c24b5ee6d259c4d2c8b46aa001000000, repr=PPO)
  File "python\ray\_raylet.pyx", line 1889, in ray._raylet.execute_task
  File "python\ray\_raylet.pyx", line 1830, in ray._raylet.execute_task.function_executor
  File "C:\Users\josep\Documents\Coup-RL\env\lib\site-packages\ray\_private\function_manager.py", line 724, in actor_method_executor
    return method(__ray_actor, *args, **kwargs)
  File "C:\Users\josep\Documents\Coup-RL\env\lib\site-packages\ray\util\tracing\tracing_helper.py", line 467, in _resume_span
    return method(self, *_args, **_kwargs)
  File "C:\Users\josep\Documents\Coup-RL\env\lib\site-packages\ray\tune\trainable\trainable.py", line 334, in train
    raise skipped from exception_cause(skipped)
  File "C:\Users\josep\Documents\Coup-RL\env\lib\site-packages\ray\tune\trainable\trainable.py", line 331, in train
    result = self.step()
  File "C:\Users\josep\Documents\Coup-RL\env\lib\site-packages\ray\util\tracing\tracing_helper.py", line 467, in _resume_span
    return method(self, *_args, **_kwargs)
  File "C:\Users\josep\Documents\Coup-RL\env\lib\site-packages\ray\rllib\algorithms\algorithm.py", line 853, in step
    results.update(self._run_one_evaluation(train_future=None))
  File "C:\Users\josep\Documents\Coup-RL\env\lib\site-packages\ray\util\tracing\tracing_helper.py", line 467, in _resume_span
    return method(self, *_args, **_kwargs)
  File "C:\Users\josep\Documents\Coup-RL\env\lib\site-packages\ray\rllib\algorithms\algorithm.py", line 3239, in _run_one_evaluation
    eval_results = eval_func_to_use()
  File "C:\Users\josep\Documents\Coup-RL\env\lib\site-packages\ray\util\tracing\tracing_helper.py", line 467, in _resume_span
    return method(self, *_args, **_kwargs)
  File "C:\Users\josep\Documents\Coup-RL\env\lib\site-packages\ray\rllib\algorithms\algorithm.py", line 948, in evaluate
    metrics = self.config.custom_evaluation_function(
  File "C:\Users\josep\Documents\Coup-RL\Coup\coup\train_ppo.py", line 132, in custom_eval_function
    metrics= eval_policy_vs_random(eval_workers)
  File "C:\Users\josep\Documents\Coup-RL\Coup\coup\train_ppo.py", line 111, in eval_policy_vs_random
    strg_rewards = [x for x in metrics["hist_stats"][f"policy_player_1_reward"] + metrics["hist_stats"][f"policy_player_2_reward"] if x not in [2, 1, -1, -2]]
KeyError: 'policy_player_2_reward'
